2024-08-07 08:04:52,592 - INFO - Starting bot
2024-08-07 08:55:22,503 - INFO - Starting bot
2024-08-07 08:55:35,124 - INFO - Starting bot
2024-08-07 08:58:14,256 - INFO - Starting bot
2024-08-07 09:36:46,714 - INFO - Starting bot
2024-08-07 09:46:45,362 - INFO - Starting bot
2024-08-07 11:46:03,655 - INFO - Starting bot
2024-08-07 11:46:17,723 - INFO - response for -1002088136062: <Response [500]>
2024-08-07 11:47:28,751 - INFO - Starting bot
2024-08-07 11:47:54,829 - INFO - response for -1002088136062: {"error":"Internal Server Error","message":"database is locked"}

2024-08-07 11:48:23,242 - INFO - response for -1002088136062: {"error":"Value Error","message":"Could not find the input entity for PeerUser(user_id=100500) (PeerUser). Please read https://docs.telethon.dev/en/stable/concepts/entities.html to find out more details."}

2024-08-08 04:10:54,679 - ERROR - Threaded polling exception: A request to the Telegram API was unsuccessful. Error code: 502. Description: Bad Gateway
2024-08-08 04:10:54,682 - ERROR - Exception traceback:
Traceback (most recent call last):
  File "D:\Projects\enot-bot-python\venv\Lib\site-packages\telebot\__init__.py", line 1215, in __threaded_polling
    polling_thread.raise_exceptions()
  File "D:\Projects\enot-bot-python\venv\Lib\site-packages\telebot\util.py", line 111, in raise_exceptions
    raise self.exception_info
  File "D:\Projects\enot-bot-python\venv\Lib\site-packages\telebot\util.py", line 93, in run
    task(*args, **kwargs)
  File "D:\Projects\enot-bot-python\venv\Lib\site-packages\telebot\__init__.py", line 677, in __retrieve_updates
    updates = self.get_updates(offset=(self.last_update_id + 1),
             ^^^^^^^^^^^^^^^^^^^^^^^^^^^^^^^^^^^^^^^^^^^^^^^^^^
  File "D:\Projects\enot-bot-python\venv\Lib\site-packages\telebot\__init__.py", line 649, in get_updates
    json_updates = apihelper.get_updates(
                   ^^^^^^^^^^^^^^^^^^^^^^
  File "D:\Projects\enot-bot-python\venv\Lib\site-packages\telebot\apihelper.py", line 330, in get_updates
    return _make_request(token, method_url, params=payload)
           ^^^^^^^^^^^^^^^^^^^^^^^^^^^^^^^^^^^^^^^^^^^^^^^^
  File "D:\Projects\enot-bot-python\venv\Lib\site-packages\telebot\apihelper.py", line 168, in _make_request
    json_result = _check_result(method_name, result)
                  ^^^^^^^^^^^^^^^^^^^^^^^^^^^^^^^^^^
  File "D:\Projects\enot-bot-python\venv\Lib\site-packages\telebot\apihelper.py", line 195, in _check_result
    raise ApiTelegramException(method_name, result, result_json)
telebot.apihelper.ApiTelegramException: A request to the Telegram API was unsuccessful. Error code: 502. Description: Bad Gateway

2024-08-08 04:50:18,168 - INFO - Starting bot
2024-08-08 05:04:54,976 - INFO - Starting bot
2024-08-08 05:09:48,676 - INFO - response for -1002088136062: {"message":"Participants saved to participants--1002088136062.json","status":"success"}

2024-08-08 05:13:33,978 - INFO - response for -1002088136062: {"message":"Participants saved to None","status":"success"}

2024-08-08 05:48:25,712 - INFO - Starting bot
2024-08-08 05:49:46,545 - INFO - Starting bot
2024-08-08 05:49:53,265 - INFO - response for -1002088136062: {"message":"Participants saved to None","status":"success"}

2024-08-08 05:53:07,500 - INFO - Starting bot
2024-08-08 05:53:22,313 - INFO - response for -1002088136062: {"message":"Participants saved to database","status":"success"}

2024-08-08 05:54:46,538 - INFO - response for -1002088136062: {"message":"Participants saved to database","status":"success"}

2024-08-08 05:55:17,276 - INFO - Starting bot
2024-08-08 05:55:27,908 - INFO - response for -1002088136062: {"message":"Participants saved to database","status":"success"}

2024-08-08 05:58:48,423 - INFO - response for -1002088136062: {"message":"Participants saved to database","status":"success"}

2024-08-08 06:01:59,552 - INFO - Starting bot
2024-08-08 06:02:15,106 - INFO - response for -1002088136062: {"message":"Participants saved to database","status":"success"}

2024-08-08 06:06:27,634 - INFO - response for -1002088136062: {"message":"Participants saved to database","status":"success"}

2024-08-08 06:07:17,159 - INFO - response for -1002088136062: {"message":"Participants saved to database","status":"success"}

2024-08-08 06:08:20,255 - INFO - response for -1002088136062: {"message":"Participants saved to database","status":"success"}

2024-08-08 06:08:38,286 - INFO - Starting bot
2024-08-08 06:08:48,510 - INFO - response for -1002088136062: {"message":"Participants saved to database","status":"success"}

2024-08-08 06:10:03,398 - INFO - Starting bot
2024-08-08 06:11:05,566 - INFO - Starting bot
2024-08-08 06:12:26,439 - INFO - Starting bot
2024-08-08 06:18:01,124 - INFO - Starting bot
2024-08-08 06:31:49,023 - INFO - Starting bot
2024-08-08 06:33:12,478 - INFO - Starting bot
2024-08-08 06:36:39,534 - INFO - Starting bot
2024-08-08 06:38:15,498 - INFO - Starting bot
2024-08-08 06:50:45,146 - INFO - Starting bot
2024-08-08 06:50:45,602 - ERROR - Threaded polling exception: A request to the Telegram API was unsuccessful. Error code: 409. Description: Conflict: terminated by other getUpdates request; make sure that only one bot instance is running
2024-08-08 06:50:45,603 - ERROR - Exception traceback:
Traceback (most recent call last):
  File "D:\Projects\enot-bot-python\venv\Lib\site-packages\telebot\__init__.py", line 1215, in __threaded_polling
    polling_thread.raise_exceptions()
  File "D:\Projects\enot-bot-python\venv\Lib\site-packages\telebot\util.py", line 111, in raise_exceptions
    raise self.exception_info
  File "D:\Projects\enot-bot-python\venv\Lib\site-packages\telebot\util.py", line 93, in run
    task(*args, **kwargs)
  File "D:\Projects\enot-bot-python\venv\Lib\site-packages\telebot\__init__.py", line 677, in __retrieve_updates
    updates = self.get_updates(offset=(self.last_update_id + 1),
             ^^^^^^^^^^^^^^^^^^^^^^^^^^^^^^^^^^^^^^^^^^^^^^^^^^
  File "D:\Projects\enot-bot-python\venv\Lib\site-packages\telebot\__init__.py", line 649, in get_updates
    json_updates = apihelper.get_updates(
                   ^^^^^^^^^^^^^^^^^^^^^^
  File "D:\Projects\enot-bot-python\venv\Lib\site-packages\telebot\apihelper.py", line 330, in get_updates
    return _make_request(token, method_url, params=payload)
           ^^^^^^^^^^^^^^^^^^^^^^^^^^^^^^^^^^^^^^^^^^^^^^^^
  File "D:\Projects\enot-bot-python\venv\Lib\site-packages\telebot\apihelper.py", line 168, in _make_request
    json_result = _check_result(method_name, result)
                  ^^^^^^^^^^^^^^^^^^^^^^^^^^^^^^^^^^
  File "D:\Projects\enot-bot-python\venv\Lib\site-packages\telebot\apihelper.py", line 195, in _check_result
    raise ApiTelegramException(method_name, result, result_json)
telebot.apihelper.ApiTelegramException: A request to the Telegram API was unsuccessful. Error code: 409. Description: Conflict: terminated by other getUpdates request; make sure that only one bot instance is running

2024-08-08 07:23:48,402 - INFO - Starting bot
2024-08-08 07:23:48,730 - ERROR - Threaded polling exception: A request to the Telegram API was unsuccessful. Error code: 409. Description: Conflict: terminated by other getUpdates request; make sure that only one bot instance is running
2024-08-08 07:23:48,731 - ERROR - Exception traceback:
Traceback (most recent call last):
  File "D:\Projects\enot-bot-python\venv\Lib\site-packages\telebot\__init__.py", line 1215, in __threaded_polling
    polling_thread.raise_exceptions()
  File "D:\Projects\enot-bot-python\venv\Lib\site-packages\telebot\util.py", line 111, in raise_exceptions
    raise self.exception_info
  File "D:\Projects\enot-bot-python\venv\Lib\site-packages\telebot\util.py", line 93, in run
    task(*args, **kwargs)
  File "D:\Projects\enot-bot-python\venv\Lib\site-packages\telebot\__init__.py", line 677, in __retrieve_updates
    updates = self.get_updates(offset=(self.last_update_id + 1),
             ^^^^^^^^^^^^^^^^^^^^^^^^^^^^^^^^^^^^^^^^^^^^^^^^^^
  File "D:\Projects\enot-bot-python\venv\Lib\site-packages\telebot\__init__.py", line 649, in get_updates
    json_updates = apihelper.get_updates(
                   ^^^^^^^^^^^^^^^^^^^^^^
  File "D:\Projects\enot-bot-python\venv\Lib\site-packages\telebot\apihelper.py", line 330, in get_updates
    return _make_request(token, method_url, params=payload)
           ^^^^^^^^^^^^^^^^^^^^^^^^^^^^^^^^^^^^^^^^^^^^^^^^
  File "D:\Projects\enot-bot-python\venv\Lib\site-packages\telebot\apihelper.py", line 168, in _make_request
    json_result = _check_result(method_name, result)
                  ^^^^^^^^^^^^^^^^^^^^^^^^^^^^^^^^^^
  File "D:\Projects\enot-bot-python\venv\Lib\site-packages\telebot\apihelper.py", line 195, in _check_result
    raise ApiTelegramException(method_name, result, result_json)
telebot.apihelper.ApiTelegramException: A request to the Telegram API was unsuccessful. Error code: 409. Description: Conflict: terminated by other getUpdates request; make sure that only one bot instance is running

2024-08-08 07:24:05,787 - INFO - response for -1002088136062: {"message":"Participants saved to database","status":"success"}

2024-08-08 07:25:16,648 - INFO - Starting bot
2024-08-08 07:25:21,441 - INFO - Starting bot
2024-08-08 07:25:35,800 - INFO - response for -1002088136062: {"message":"Participants saved to database","status":"success"}

2024-08-08 07:26:03,596 - INFO - Starting bot
2024-08-08 07:26:11,974 - INFO - response for -1002088136062: {"message":"Participants saved to database","status":"success"}

2024-08-08 07:28:32,310 - INFO - Starting bot
2024-08-08 07:29:25,542 - INFO - Starting bot
2024-08-08 07:30:06,905 - INFO - response for -1002103659934: {"error":"Internal Server Error","message":"database is locked"}

2024-08-08 07:32:56,814 - INFO - response for -1002088136062: {"error":"Internal Server Error","message":"database is locked"}

2024-08-08 07:33:06,202 - INFO - Starting bot
2024-08-08 07:33:24,809 - INFO - response for -1002088136062: {"message":"Participants saved to database","status":"success"}

2024-08-08 07:34:28,222 - INFO - Starting bot
2024-08-08 07:34:52,741 - INFO - response for -1002088136062: {"message":"Participants saved to database","status":"success"}

2024-08-08 07:35:06,153 - INFO - response for -1002088136062: {"error":"Internal Server Error","message":"database is locked"}

2024-08-08 07:36:17,196 - INFO - response for -1002088136062: {"message":"Participants saved to database","status":"success"}

2024-08-08 07:42:07,752 - INFO - Starting bot
2024-08-08 07:42:25,383 - INFO - response for -1002088136062: {"message":"Participants saved to database","status":"success"}

2024-08-08 07:42:35,228 - INFO - response for -1002088136062: {"message":"Participants saved to database","status":"success"}

2024-08-08 07:47:27,916 - INFO - Starting bot
2024-08-08 07:47:45,449 - INFO - response for -1002088136062: {"message":"Participants saved to database","status":"success"}

2024-08-08 07:47:56,661 - INFO - response for -1002088136062: {"message":"Participants saved to database","status":"success"}

2024-08-08 07:48:13,223 - INFO - response for -1002088136062: {"message":"Participants saved to database","status":"success"}

2024-08-08 07:48:57,060 - INFO - response for -1002088136062: {"message":"Participants saved to database","status":"success"}

2024-08-08 07:49:26,922 - INFO - response for -1002088136062: {"message":"Participants saved to database","status":"success"}

2024-08-08 07:49:36,875 - INFO - response for -1002088136062: {"message":"Participants saved to database","status":"success"}

2024-08-08 08:15:45,024 - INFO - Starting bot
2024-08-08 08:15:55,021 - INFO - response for -1002088136062: {"message":"Participants saved to database","status":"success"}

2024-08-08 08:16:01,231 - INFO - response for -1002088136062: {"message":"Participants saved to database","status":"success"}

2024-08-08 08:16:27,524 - INFO - response for -1002103659934: {"message":"Participants saved to database","status":"success"}

2024-08-09 02:47:23,265 - INFO - Starting bot
2024-08-09 02:49:46,988 - INFO - response for -1002088136062: {"message":"Participants saved to database","status":"success"}

2024-08-09 02:51:46,650 - INFO - response for -1002088136062: {"message":"Participants saved to database","status":"success"}

2024-08-09 02:51:58,908 - INFO - response for -1002103659934: {"message":"Participants saved to database","status":"success"}

2024-08-09 04:03:34,758 - INFO - Starting bot
2024-08-09 04:06:30,947 - INFO - response for -1002088136062: {"error":"Internal Server Error","message":"'User' object has no attribute 'first_named'"}

2024-08-09 04:06:54,806 - INFO - response for -1002088136062: {"message":"Participants saved to database","status":"success"}

2024-08-09 04:10:48,861 - ERROR - Threaded polling exception: A request to the Telegram API was unsuccessful. Error code: 502. Description: Bad Gateway
2024-08-09 04:10:48,861 - ERROR - Exception traceback:
Traceback (most recent call last):
  File "D:\Projects\enot-bot-python\venv\Lib\site-packages\telebot\__init__.py", line 1215, in __threaded_polling
    polling_thread.raise_exceptions()
  File "D:\Projects\enot-bot-python\venv\Lib\site-packages\telebot\util.py", line 111, in raise_exceptions
    raise self.exception_info
  File "D:\Projects\enot-bot-python\venv\Lib\site-packages\telebot\util.py", line 93, in run
    task(*args, **kwargs)
  File "D:\Projects\enot-bot-python\venv\Lib\site-packages\telebot\__init__.py", line 677, in __retrieve_updates
    updates = self.get_updates(offset=(self.last_update_id + 1),
             ^^^^^^^^^^^^^^^^^^^^^^^^^^^^^^^^^^^^^^^^^^^^^^^^^^
  File "D:\Projects\enot-bot-python\venv\Lib\site-packages\telebot\__init__.py", line 649, in get_updates
    json_updates = apihelper.get_updates(
                   ^^^^^^^^^^^^^^^^^^^^^^
  File "D:\Projects\enot-bot-python\venv\Lib\site-packages\telebot\apihelper.py", line 330, in get_updates
    return _make_request(token, method_url, params=payload)
           ^^^^^^^^^^^^^^^^^^^^^^^^^^^^^^^^^^^^^^^^^^^^^^^^
  File "D:\Projects\enot-bot-python\venv\Lib\site-packages\telebot\apihelper.py", line 168, in _make_request
    json_result = _check_result(method_name, result)
                  ^^^^^^^^^^^^^^^^^^^^^^^^^^^^^^^^^^
  File "D:\Projects\enot-bot-python\venv\Lib\site-packages\telebot\apihelper.py", line 195, in _check_result
    raise ApiTelegramException(method_name, result, result_json)
telebot.apihelper.ApiTelegramException: A request to the Telegram API was unsuccessful. Error code: 502. Description: Bad Gateway

2024-08-09 04:14:20,716 - INFO - Starting bot
2024-08-09 04:14:48,308 - ERROR - Threaded polling exception: A request to the Telegram API was unsuccessful. Error code: 400. Description: Bad Request: invalid user_id specified
2024-08-09 04:14:48,309 - ERROR - Exception traceback:
Traceback (most recent call last):
  File "D:\Projects\enot-bot-python\venv\Lib\site-packages\telebot\__init__.py", line 1216, in __threaded_polling
    self.worker_pool.raise_exceptions()
  File "D:\Projects\enot-bot-python\venv\Lib\site-packages\telebot\util.py", line 150, in raise_exceptions
    raise self.exception_info
  File "D:\Projects\enot-bot-python\venv\Lib\site-packages\telebot\util.py", line 93, in run
    task(*args, **kwargs)
  File "D:\Projects\enot-bot-python\venv\Lib\site-packages\telebot\__init__.py", line 8715, in _run_middlewares_and_handler
    result = handler['function'](message)
             ^^^^^^^^^^^^^^^^^^^^^^^^^^^^
  File "D:\Projects\enot-bot-python\src\bot\bot.py", line 109, in handle_text_message
    chat_member = bot.get_chat_member(message.chat.id, mentioned_user_id)
                  ^^^^^^^^^^^^^^^^^^^^^^^^^^^^^^^^^^^^^^^^^^^^^^^^^^^^^^^
  File "D:\Projects\enot-bot-python\venv\Lib\site-packages\telebot\__init__.py", line 1635, in get_chat_member
    apihelper.get_chat_member(self.token, chat_id, user_id)
  File "D:\Projects\enot-bot-python\venv\Lib\site-packages\telebot\apihelper.py", line 410, in get_chat_member
    return _make_request(token, method_url, params=payload)
           ^^^^^^^^^^^^^^^^^^^^^^^^^^^^^^^^^^^^^^^^^^^^^^^^
  File "D:\Projects\enot-bot-python\venv\Lib\site-packages\telebot\apihelper.py", line 168, in _make_request
    json_result = _check_result(method_name, result)
                  ^^^^^^^^^^^^^^^^^^^^^^^^^^^^^^^^^^
  File "D:\Projects\enot-bot-python\venv\Lib\site-packages\telebot\apihelper.py", line 195, in _check_result
    raise ApiTelegramException(method_name, result, result_json)
telebot.apihelper.ApiTelegramException: A request to the Telegram API was unsuccessful. Error code: 400. Description: Bad Request: invalid user_id specified

2024-08-09 04:18:57,919 - INFO - Starting bot
2024-08-09 04:19:01,855 - ERROR - Threaded polling exception: A request to the Telegram API was unsuccessful. Error code: 400. Description: Bad Request: invalid user_id specified
2024-08-09 04:19:01,855 - ERROR - Exception traceback:
Traceback (most recent call last):
  File "D:\Projects\enot-bot-python\venv\Lib\site-packages\telebot\__init__.py", line 1216, in __threaded_polling
    self.worker_pool.raise_exceptions()
  File "D:\Projects\enot-bot-python\venv\Lib\site-packages\telebot\util.py", line 150, in raise_exceptions
    raise self.exception_info
  File "D:\Projects\enot-bot-python\venv\Lib\site-packages\telebot\util.py", line 93, in run
    task(*args, **kwargs)
  File "D:\Projects\enot-bot-python\venv\Lib\site-packages\telebot\__init__.py", line 8715, in _run_middlewares_and_handler
    result = handler['function'](message)
             ^^^^^^^^^^^^^^^^^^^^^^^^^^^^
  File "D:\Projects\enot-bot-python\src\bot\bot.py", line 110, in handle_text_message
    chat_member = bot.get_chat_member(message.chat.id, mentioned_user_id)
                  ^^^^^^^^^^^^^^^^^^^^^^^^^^^^^^^^^^^^^^^^^^^^^^^^^^^^^^^
  File "D:\Projects\enot-bot-python\venv\Lib\site-packages\telebot\__init__.py", line 1635, in get_chat_member
    apihelper.get_chat_member(self.token, chat_id, user_id)
  File "D:\Projects\enot-bot-python\venv\Lib\site-packages\telebot\apihelper.py", line 410, in get_chat_member
    return _make_request(token, method_url, params=payload)
           ^^^^^^^^^^^^^^^^^^^^^^^^^^^^^^^^^^^^^^^^^^^^^^^^
  File "D:\Projects\enot-bot-python\venv\Lib\site-packages\telebot\apihelper.py", line 168, in _make_request
    json_result = _check_result(method_name, result)
                  ^^^^^^^^^^^^^^^^^^^^^^^^^^^^^^^^^^
  File "D:\Projects\enot-bot-python\venv\Lib\site-packages\telebot\apihelper.py", line 195, in _check_result
    raise ApiTelegramException(method_name, result, result_json)
telebot.apihelper.ApiTelegramException: A request to the Telegram API was unsuccessful. Error code: 400. Description: Bad Request: invalid user_id specified

2024-08-09 05:02:23,856 - INFO - Starting bot
2024-08-09 05:02:49,544 - INFO - Starting bot
2024-08-09 05:14:22,202 - INFO - Starting bot
2024-08-09 05:14:37,352 - INFO - response for -1002088136062: {"error":"Internal Server Error","message":"Could not determine join condition between parent/child tables on relationship Team.participants - there are multiple foreign key paths linking the tables.  Specify the 'foreign_keys' argument, providing a list of those columns which should be counted as containing a foreign key reference to the parent table."}

2024-08-09 05:18:00,442 - INFO - response for -1002088136062: {"error":"Internal Server Error","message":"One or more mappers failed to initialize - can't proceed with initialization of other mappers. Triggering mapper: 'Mapper[Team(teams)]'. Original exception was: Could not determine join condition between parent/child tables on relationship Team.participants - there are multiple foreign key paths linking the tables.  Specify the 'foreign_keys' argument, providing a list of those columns which should be counted as containing a foreign key reference to the parent table."}

2024-08-09 05:18:11,307 - INFO - Starting bot
2024-08-09 05:18:21,318 - INFO - response for -1002088136062: {"error":"Internal Server Error","message":"Could not determine join condition between parent/child tables on relationship Team.participants - there are multiple foreign key paths linking the tables.  Specify the 'foreign_keys' argument, providing a list of those columns which should be counted as containing a foreign key reference to the parent table."}

2024-08-09 05:20:56,372 - INFO - response for -1002088136062: {"error":"Internal Server Error","message":"Could not determine join condition between parent/child tables on relationship Team.participants - there are multiple foreign key paths linking the tables.  Specify the 'foreign_keys' argument, providing a list of those columns which should be counted as containing a foreign key reference to the parent table."}

2024-08-09 05:57:04,092 - INFO - Starting bot
2024-08-09 05:57:30,044 - INFO - response for -1002088136062: {"error":"Internal Server Error","message":"Error creating backref 'participants' on relationship 'ParticipantGroup.group': property of that name exists on mapper 'Mapper[Group(groups)]'"}

2024-08-09 05:59:29,869 - INFO - Starting bot
2024-08-09 06:00:42,162 - INFO - response for -1002088136062: {"error":"Internal Server Error","message":"Mapper 'Mapper[Participant(participants)]' has no property 'group_associations'.  If this property was indicated from other mappers or configure events, ensure registry.configure() has been called."}

2024-08-09 06:01:40,461 - INFO - response for -1002088136062: {"error":"Internal Server Error","message":"Could not determine join condition between parent/child tables on relationship Team.participants - there are multiple foreign key paths linking the tables.  Specify the 'foreign_keys' argument, providing a list of those columns which should be counted as containing a foreign key reference to the parent table."}

2024-08-09 06:02:51,645 - INFO - response for -1002088136062: {"error":"Internal Server Error","message":"Could not determine join condition between parent/child tables on relationship Team.participants - there are multiple foreign key paths linking the tables.  Specify the 'foreign_keys' argument, providing a list of those columns which should be counted as containing a foreign key reference to the parent table."}

2024-08-09 06:03:41,078 - INFO - Starting bot
2024-08-09 06:03:52,353 - INFO - response for -1002088136062: {"error":"Internal Server Error","message":"Could not determine join condition between parent/child tables on relationship Team.participants - there are multiple foreign key paths linking the tables.  Specify the 'foreign_keys' argument, providing a list of those columns which should be counted as containing a foreign key reference to the parent table."}

2024-08-09 06:04:48,641 - INFO - response for -1002088136062: {"error":"Internal Server Error","message":"Could not determine join condition between parent/child tables on relationship Team.participants - there are multiple foreign key paths linking the tables.  Specify the 'foreign_keys' argument, providing a list of those columns which should be counted as containing a foreign key reference to the parent table."}

2024-08-09 06:18:24,639 - INFO - Starting bot
2024-08-09 06:18:31,567 - INFO - response for -1002088136062: {"message":"Participants saved to database","status":"success"}

2024-08-09 06:18:40,245 - INFO - response for -1002088136062: {"message":"Participants saved to database","status":"success"}

2024-08-09 06:20:30,353 - INFO - Starting bot
2024-08-09 06:21:46,308 - INFO - response for -1002088136062: {"error":"Internal Server Error","message":"Could not determine join condition between parent/child tables on relationship Team.participants - there are multiple foreign key paths linking the tables.  Specify the 'foreign_keys' argument, providing a list of those columns which should be counted as containing a foreign key reference to the parent table."}

2024-08-09 06:24:01,090 - INFO - response for -1002088136062: {"error":"Internal Server Error","message":"Could not determine join condition between parent/child tables on relationship Team.participants - there are multiple foreign key paths linking the tables.  Specify the 'foreign_keys' argument, providing a list of those columns which should be counted as containing a foreign key reference to the parent table."}

2024-08-09 06:30:33,394 - INFO - response for -1002088136062: {"error":"Internal Server Error","message":"Could not determine join condition between parent/child tables on relationship Team.team_participants - there are multiple foreign key paths linking the tables.  Specify the 'foreign_keys' argument, providing a list of those columns which should be counted as containing a foreign key reference to the parent table."}

2024-08-09 06:31:07,195 - INFO - response for -1002088136062: {"error":"Internal Server Error","message":"Could not determine join condition between parent/child tables on relationship Team.team_participants - there are multiple foreign key paths linking the tables.  Specify the 'foreign_keys' argument, providing a list of those columns which should be counted as containing a foreign key reference to the parent table."}

2024-08-09 06:31:32,622 - INFO - response for -1002088136062: {"error":"Internal Server Error","message":"Could not determine join condition between parent/child tables on relationship Team.team_participants - there are no foreign keys linking these tables.  Ensure that referencing columns are associated with a ForeignKey or ForeignKeyConstraint, or specify a 'primaryjoin' expression."}

2024-08-09 06:33:22,014 - INFO - response for -1002088136062: {"message":"Participants saved to database","status":"success"}

2024-08-09 06:51:51,477 - INFO - Starting bot
2024-08-09 06:52:07,100 - INFO - response for -1002088136062: {"message":"Participants saved to database","status":"success"}

2024-08-09 07:03:29,424 - INFO - Starting bot
2024-08-09 07:07:50,751 - INFO - Starting bot
2024-08-09 07:09:40,115 - INFO - Starting bot
2024-08-09 07:14:10,299 - INFO - Starting bot
2024-08-09 07:21:23,590 - INFO - Starting bot
2024-08-09 07:22:05,391 - INFO - Starting bot
2024-08-09 07:22:41,643 - INFO - Starting bot
2024-08-09 07:41:36,291 - INFO - Starting bot
2024-08-09 07:42:35,456 - INFO - Starting bot
2024-08-09 08:21:27,877 - INFO - Starting bot
2024-08-09 08:24:38,374 - INFO - Starting bot
2024-08-09 08:39:19,336 - INFO - Starting bot
2024-08-09 08:40:14,574 - INFO - response for -1002088136062: {"message":"Participants saved to database","status":"success"}

2024-08-09 08:42:34,335 - ERROR - Error occurred: handle_team_set() takes 1 positional argument but 2 were given
2024-08-09 08:43:41,239 - ERROR - Error occurred: handle_team_set() takes 1 positional argument but 2 were given
2024-08-09 08:45:20,372 - INFO - Starting bot
2024-08-09 08:50:19,712 - INFO - response for -1002103659934: {"message":"Participants saved to database","status":"success"}

2024-08-10 04:10:53,193 - ERROR - Threaded polling exception: A request to the Telegram API was unsuccessful. Error code: 502. Description: Bad Gateway
2024-08-10 04:10:53,195 - ERROR - Exception traceback:
Traceback (most recent call last):
  File "D:\Projects\enot-bot-python\venv\Lib\site-packages\telebot\__init__.py", line 1215, in __threaded_polling
    polling_thread.raise_exceptions()
  File "D:\Projects\enot-bot-python\venv\Lib\site-packages\telebot\util.py", line 111, in raise_exceptions
    raise self.exception_info
  File "D:\Projects\enot-bot-python\venv\Lib\site-packages\telebot\util.py", line 93, in run
    task(*args, **kwargs)
  File "D:\Projects\enot-bot-python\venv\Lib\site-packages\telebot\__init__.py", line 677, in __retrieve_updates
    updates = self.get_updates(offset=(self.last_update_id + 1),
             ^^^^^^^^^^^^^^^^^^^^^^^^^^^^^^^^^^^^^^^^^^^^^^^^^^
  File "D:\Projects\enot-bot-python\venv\Lib\site-packages\telebot\__init__.py", line 649, in get_updates
    json_updates = apihelper.get_updates(
                   ^^^^^^^^^^^^^^^^^^^^^^
  File "D:\Projects\enot-bot-python\venv\Lib\site-packages\telebot\apihelper.py", line 330, in get_updates
    return _make_request(token, method_url, params=payload)
           ^^^^^^^^^^^^^^^^^^^^^^^^^^^^^^^^^^^^^^^^^^^^^^^^
  File "D:\Projects\enot-bot-python\venv\Lib\site-packages\telebot\apihelper.py", line 168, in _make_request
    json_result = _check_result(method_name, result)
                  ^^^^^^^^^^^^^^^^^^^^^^^^^^^^^^^^^^
  File "D:\Projects\enot-bot-python\venv\Lib\site-packages\telebot\apihelper.py", line 195, in _check_result
    raise ApiTelegramException(method_name, result, result_json)
telebot.apihelper.ApiTelegramException: A request to the Telegram API was unsuccessful. Error code: 502. Description: Bad Gateway

2024-08-10 06:26:21,762 - INFO - Starting bot
2024-08-10 06:36:07,530 - INFO - Starting bot
2024-08-10 06:36:14,510 - INFO - Starting bot
2024-08-10 06:36:37,529 - ERROR - Error occurred: 'str' object has no attribute 'name'
2024-08-10 06:37:21,496 - INFO - Starting bot
2024-08-10 06:37:25,969 - ERROR - Error occurred: 'str' object has no attribute 'team_name'
2024-08-10 06:37:58,764 - INFO - Starting bot
2024-08-10 06:38:22,255 - INFO - Starting bot
2024-08-10 06:38:45,577 - INFO - Starting bot
2024-08-10 06:39:17,552 - INFO - Starting bot
2024-08-10 06:40:28,315 - INFO - Starting bot
2024-08-10 06:44:22,305 - INFO - Starting bot
2024-08-10 13:20:14,131 - INFO - response for -1002088136062: {"message":"Participants saved to database","status":"success"}

2024-08-11 04:48:55,791 - INFO - Starting bot
2024-08-11 04:49:44,116 - ERROR - Error occurred: HTTPConnectionPool(host='localhost', port=5000): Max retries exceeded with url: /update_participants/-1002088136062 (Caused by NewConnectionError('<urllib3.connection.HTTPConnection object at 0x000001DD3966E990>: Failed to establish a new connection: [WinError 10061] Подключение не установлено, т.к. конечный компьютер отверг запрос на подключение'))
2024-08-11 04:50:40,395 - INFO - response for -1002088136062: {"message":"Participants saved to database","status":"success"}

2024-08-11 04:53:00,764 - INFO - response for -1002088136062: {"message":"Participants saved to database","status":"success"}

2024-08-11 04:53:17,207 - INFO - response for -1002088136062: {"message":"Participants saved to database","status":"success"}

2024-08-11 04:54:50,338 - INFO - Starting bot
2024-08-11 04:54:50,734 - ERROR - Threaded polling exception: A request to the Telegram API was unsuccessful. Error code: 409. Description: Conflict: terminated by other getUpdates request; make sure that only one bot instance is running
2024-08-11 04:54:50,735 - ERROR - Exception traceback:
Traceback (most recent call last):
  File "D:\Projects\enot-bot-python\venv\Lib\site-packages\telebot\__init__.py", line 1215, in __threaded_polling
    polling_thread.raise_exceptions()
  File "D:\Projects\enot-bot-python\venv\Lib\site-packages\telebot\util.py", line 111, in raise_exceptions
    raise self.exception_info
  File "D:\Projects\enot-bot-python\venv\Lib\site-packages\telebot\util.py", line 93, in run
    task(*args, **kwargs)
  File "D:\Projects\enot-bot-python\venv\Lib\site-packages\telebot\__init__.py", line 677, in __retrieve_updates
    updates = self.get_updates(offset=(self.last_update_id + 1),
             ^^^^^^^^^^^^^^^^^^^^^^^^^^^^^^^^^^^^^^^^^^^^^^^^^^
  File "D:\Projects\enot-bot-python\venv\Lib\site-packages\telebot\__init__.py", line 649, in get_updates
    json_updates = apihelper.get_updates(
                   ^^^^^^^^^^^^^^^^^^^^^^
  File "D:\Projects\enot-bot-python\venv\Lib\site-packages\telebot\apihelper.py", line 330, in get_updates
    return _make_request(token, method_url, params=payload)
           ^^^^^^^^^^^^^^^^^^^^^^^^^^^^^^^^^^^^^^^^^^^^^^^^
  File "D:\Projects\enot-bot-python\venv\Lib\site-packages\telebot\apihelper.py", line 168, in _make_request
    json_result = _check_result(method_name, result)
                  ^^^^^^^^^^^^^^^^^^^^^^^^^^^^^^^^^^
  File "D:\Projects\enot-bot-python\venv\Lib\site-packages\telebot\apihelper.py", line 195, in _check_result
    raise ApiTelegramException(method_name, result, result_json)
telebot.apihelper.ApiTelegramException: A request to the Telegram API was unsuccessful. Error code: 409. Description: Conflict: terminated by other getUpdates request; make sure that only one bot instance is running

2024-08-11 04:54:53,892 - ERROR - Threaded polling exception: A request to the Telegram API was unsuccessful. Error code: 409. Description: Conflict: terminated by other getUpdates request; make sure that only one bot instance is running
2024-08-11 04:54:53,893 - ERROR - Exception traceback:
Traceback (most recent call last):
  File "D:\Projects\enot-bot-python\venv\Lib\site-packages\telebot\__init__.py", line 1215, in __threaded_polling
    polling_thread.raise_exceptions()
  File "D:\Projects\enot-bot-python\venv\Lib\site-packages\telebot\util.py", line 111, in raise_exceptions
    raise self.exception_info
  File "D:\Projects\enot-bot-python\venv\Lib\site-packages\telebot\util.py", line 93, in run
    task(*args, **kwargs)
  File "D:\Projects\enot-bot-python\venv\Lib\site-packages\telebot\__init__.py", line 677, in __retrieve_updates
    updates = self.get_updates(offset=(self.last_update_id + 1),
             ^^^^^^^^^^^^^^^^^^^^^^^^^^^^^^^^^^^^^^^^^^^^^^^^^^
  File "D:\Projects\enot-bot-python\venv\Lib\site-packages\telebot\__init__.py", line 649, in get_updates
    json_updates = apihelper.get_updates(
                   ^^^^^^^^^^^^^^^^^^^^^^
  File "D:\Projects\enot-bot-python\venv\Lib\site-packages\telebot\apihelper.py", line 330, in get_updates
    return _make_request(token, method_url, params=payload)
           ^^^^^^^^^^^^^^^^^^^^^^^^^^^^^^^^^^^^^^^^^^^^^^^^
  File "D:\Projects\enot-bot-python\venv\Lib\site-packages\telebot\apihelper.py", line 168, in _make_request
    json_result = _check_result(method_name, result)
                  ^^^^^^^^^^^^^^^^^^^^^^^^^^^^^^^^^^
  File "D:\Projects\enot-bot-python\venv\Lib\site-packages\telebot\apihelper.py", line 195, in _check_result
    raise ApiTelegramException(method_name, result, result_json)
telebot.apihelper.ApiTelegramException: A request to the Telegram API was unsuccessful. Error code: 409. Description: Conflict: terminated by other getUpdates request; make sure that only one bot instance is running

2024-08-11 04:54:54,044 - ERROR - Threaded polling exception: A request to the Telegram API was unsuccessful. Error code: 409. Description: Conflict: terminated by other getUpdates request; make sure that only one bot instance is running
2024-08-11 04:54:54,045 - ERROR - Exception traceback:
Traceback (most recent call last):
  File "D:\Projects\enot-bot-python\venv\Lib\site-packages\telebot\__init__.py", line 1215, in __threaded_polling
    polling_thread.raise_exceptions()
  File "D:\Projects\enot-bot-python\venv\Lib\site-packages\telebot\util.py", line 111, in raise_exceptions
    raise self.exception_info
  File "D:\Projects\enot-bot-python\venv\Lib\site-packages\telebot\util.py", line 93, in run
    task(*args, **kwargs)
  File "D:\Projects\enot-bot-python\venv\Lib\site-packages\telebot\__init__.py", line 677, in __retrieve_updates
    updates = self.get_updates(offset=(self.last_update_id + 1),
             ^^^^^^^^^^^^^^^^^^^^^^^^^^^^^^^^^^^^^^^^^^^^^^^^^^
  File "D:\Projects\enot-bot-python\venv\Lib\site-packages\telebot\__init__.py", line 649, in get_updates
    json_updates = apihelper.get_updates(
                   ^^^^^^^^^^^^^^^^^^^^^^
  File "D:\Projects\enot-bot-python\venv\Lib\site-packages\telebot\apihelper.py", line 330, in get_updates
    return _make_request(token, method_url, params=payload)
           ^^^^^^^^^^^^^^^^^^^^^^^^^^^^^^^^^^^^^^^^^^^^^^^^
  File "D:\Projects\enot-bot-python\venv\Lib\site-packages\telebot\apihelper.py", line 168, in _make_request
    json_result = _check_result(method_name, result)
                  ^^^^^^^^^^^^^^^^^^^^^^^^^^^^^^^^^^
  File "D:\Projects\enot-bot-python\venv\Lib\site-packages\telebot\apihelper.py", line 195, in _check_result
    raise ApiTelegramException(method_name, result, result_json)
telebot.apihelper.ApiTelegramException: A request to the Telegram API was unsuccessful. Error code: 409. Description: Conflict: terminated by other getUpdates request; make sure that only one bot instance is running

2024-08-11 04:54:57,204 - ERROR - Threaded polling exception: A request to the Telegram API was unsuccessful. Error code: 409. Description: Conflict: terminated by other getUpdates request; make sure that only one bot instance is running
2024-08-11 04:54:57,206 - ERROR - Exception traceback:
Traceback (most recent call last):
  File "D:\Projects\enot-bot-python\venv\Lib\site-packages\telebot\__init__.py", line 1215, in __threaded_polling
    polling_thread.raise_exceptions()
  File "D:\Projects\enot-bot-python\venv\Lib\site-packages\telebot\util.py", line 111, in raise_exceptions
    raise self.exception_info
  File "D:\Projects\enot-bot-python\venv\Lib\site-packages\telebot\util.py", line 93, in run
    task(*args, **kwargs)
  File "D:\Projects\enot-bot-python\venv\Lib\site-packages\telebot\__init__.py", line 677, in __retrieve_updates
    updates = self.get_updates(offset=(self.last_update_id + 1),
             ^^^^^^^^^^^^^^^^^^^^^^^^^^^^^^^^^^^^^^^^^^^^^^^^^^
  File "D:\Projects\enot-bot-python\venv\Lib\site-packages\telebot\__init__.py", line 649, in get_updates
    json_updates = apihelper.get_updates(
                   ^^^^^^^^^^^^^^^^^^^^^^
  File "D:\Projects\enot-bot-python\venv\Lib\site-packages\telebot\apihelper.py", line 330, in get_updates
    return _make_request(token, method_url, params=payload)
           ^^^^^^^^^^^^^^^^^^^^^^^^^^^^^^^^^^^^^^^^^^^^^^^^
  File "D:\Projects\enot-bot-python\venv\Lib\site-packages\telebot\apihelper.py", line 168, in _make_request
    json_result = _check_result(method_name, result)
                  ^^^^^^^^^^^^^^^^^^^^^^^^^^^^^^^^^^
  File "D:\Projects\enot-bot-python\venv\Lib\site-packages\telebot\apihelper.py", line 195, in _check_result
    raise ApiTelegramException(method_name, result, result_json)
telebot.apihelper.ApiTelegramException: A request to the Telegram API was unsuccessful. Error code: 409. Description: Conflict: terminated by other getUpdates request; make sure that only one bot instance is running

2024-08-11 04:54:57,370 - ERROR - Threaded polling exception: A request to the Telegram API was unsuccessful. Error code: 409. Description: Conflict: terminated by other getUpdates request; make sure that only one bot instance is running
2024-08-11 04:54:57,370 - ERROR - Exception traceback:
Traceback (most recent call last):
  File "D:\Projects\enot-bot-python\venv\Lib\site-packages\telebot\__init__.py", line 1215, in __threaded_polling
    polling_thread.raise_exceptions()
  File "D:\Projects\enot-bot-python\venv\Lib\site-packages\telebot\util.py", line 111, in raise_exceptions
    raise self.exception_info
  File "D:\Projects\enot-bot-python\venv\Lib\site-packages\telebot\util.py", line 93, in run
    task(*args, **kwargs)
  File "D:\Projects\enot-bot-python\venv\Lib\site-packages\telebot\__init__.py", line 677, in __retrieve_updates
    updates = self.get_updates(offset=(self.last_update_id + 1),
             ^^^^^^^^^^^^^^^^^^^^^^^^^^^^^^^^^^^^^^^^^^^^^^^^^^
  File "D:\Projects\enot-bot-python\venv\Lib\site-packages\telebot\__init__.py", line 649, in get_updates
    json_updates = apihelper.get_updates(
                   ^^^^^^^^^^^^^^^^^^^^^^
  File "D:\Projects\enot-bot-python\venv\Lib\site-packages\telebot\apihelper.py", line 330, in get_updates
    return _make_request(token, method_url, params=payload)
           ^^^^^^^^^^^^^^^^^^^^^^^^^^^^^^^^^^^^^^^^^^^^^^^^
  File "D:\Projects\enot-bot-python\venv\Lib\site-packages\telebot\apihelper.py", line 168, in _make_request
    json_result = _check_result(method_name, result)
                  ^^^^^^^^^^^^^^^^^^^^^^^^^^^^^^^^^^
  File "D:\Projects\enot-bot-python\venv\Lib\site-packages\telebot\apihelper.py", line 195, in _check_result
    raise ApiTelegramException(method_name, result, result_json)
telebot.apihelper.ApiTelegramException: A request to the Telegram API was unsuccessful. Error code: 409. Description: Conflict: terminated by other getUpdates request; make sure that only one bot instance is running

2024-08-11 04:55:00,523 - ERROR - Threaded polling exception: A request to the Telegram API was unsuccessful. Error code: 409. Description: Conflict: terminated by other getUpdates request; make sure that only one bot instance is running
2024-08-11 04:55:00,524 - ERROR - Exception traceback:
Traceback (most recent call last):
  File "D:\Projects\enot-bot-python\venv\Lib\site-packages\telebot\__init__.py", line 1215, in __threaded_polling
    polling_thread.raise_exceptions()
  File "D:\Projects\enot-bot-python\venv\Lib\site-packages\telebot\util.py", line 111, in raise_exceptions
    raise self.exception_info
  File "D:\Projects\enot-bot-python\venv\Lib\site-packages\telebot\util.py", line 93, in run
    task(*args, **kwargs)
  File "D:\Projects\enot-bot-python\venv\Lib\site-packages\telebot\__init__.py", line 677, in __retrieve_updates
    updates = self.get_updates(offset=(self.last_update_id + 1),
             ^^^^^^^^^^^^^^^^^^^^^^^^^^^^^^^^^^^^^^^^^^^^^^^^^^
  File "D:\Projects\enot-bot-python\venv\Lib\site-packages\telebot\__init__.py", line 649, in get_updates
    json_updates = apihelper.get_updates(
                   ^^^^^^^^^^^^^^^^^^^^^^
  File "D:\Projects\enot-bot-python\venv\Lib\site-packages\telebot\apihelper.py", line 330, in get_updates
    return _make_request(token, method_url, params=payload)
           ^^^^^^^^^^^^^^^^^^^^^^^^^^^^^^^^^^^^^^^^^^^^^^^^
  File "D:\Projects\enot-bot-python\venv\Lib\site-packages\telebot\apihelper.py", line 168, in _make_request
    json_result = _check_result(method_name, result)
                  ^^^^^^^^^^^^^^^^^^^^^^^^^^^^^^^^^^
  File "D:\Projects\enot-bot-python\venv\Lib\site-packages\telebot\apihelper.py", line 195, in _check_result
    raise ApiTelegramException(method_name, result, result_json)
telebot.apihelper.ApiTelegramException: A request to the Telegram API was unsuccessful. Error code: 409. Description: Conflict: terminated by other getUpdates request; make sure that only one bot instance is running

2024-08-11 04:55:03,669 - ERROR - Threaded polling exception: A request to the Telegram API was unsuccessful. Error code: 409. Description: Conflict: terminated by other getUpdates request; make sure that only one bot instance is running
2024-08-11 04:55:03,670 - ERROR - Exception traceback:
Traceback (most recent call last):
  File "D:\Projects\enot-bot-python\venv\Lib\site-packages\telebot\__init__.py", line 1215, in __threaded_polling
    polling_thread.raise_exceptions()
  File "D:\Projects\enot-bot-python\venv\Lib\site-packages\telebot\util.py", line 111, in raise_exceptions
    raise self.exception_info
  File "D:\Projects\enot-bot-python\venv\Lib\site-packages\telebot\util.py", line 93, in run
    task(*args, **kwargs)
  File "D:\Projects\enot-bot-python\venv\Lib\site-packages\telebot\__init__.py", line 677, in __retrieve_updates
    updates = self.get_updates(offset=(self.last_update_id + 1),
             ^^^^^^^^^^^^^^^^^^^^^^^^^^^^^^^^^^^^^^^^^^^^^^^^^^
  File "D:\Projects\enot-bot-python\venv\Lib\site-packages\telebot\__init__.py", line 649, in get_updates
    json_updates = apihelper.get_updates(
                   ^^^^^^^^^^^^^^^^^^^^^^
  File "D:\Projects\enot-bot-python\venv\Lib\site-packages\telebot\apihelper.py", line 330, in get_updates
    return _make_request(token, method_url, params=payload)
           ^^^^^^^^^^^^^^^^^^^^^^^^^^^^^^^^^^^^^^^^^^^^^^^^
  File "D:\Projects\enot-bot-python\venv\Lib\site-packages\telebot\apihelper.py", line 168, in _make_request
    json_result = _check_result(method_name, result)
                  ^^^^^^^^^^^^^^^^^^^^^^^^^^^^^^^^^^
  File "D:\Projects\enot-bot-python\venv\Lib\site-packages\telebot\apihelper.py", line 195, in _check_result
    raise ApiTelegramException(method_name, result, result_json)
telebot.apihelper.ApiTelegramException: A request to the Telegram API was unsuccessful. Error code: 409. Description: Conflict: terminated by other getUpdates request; make sure that only one bot instance is running

2024-08-11 04:55:03,820 - ERROR - Threaded polling exception: A request to the Telegram API was unsuccessful. Error code: 409. Description: Conflict: terminated by other getUpdates request; make sure that only one bot instance is running
2024-08-11 04:55:03,821 - ERROR - Exception traceback:
Traceback (most recent call last):
  File "D:\Projects\enot-bot-python\venv\Lib\site-packages\telebot\__init__.py", line 1215, in __threaded_polling
    polling_thread.raise_exceptions()
  File "D:\Projects\enot-bot-python\venv\Lib\site-packages\telebot\util.py", line 111, in raise_exceptions
    raise self.exception_info
  File "D:\Projects\enot-bot-python\venv\Lib\site-packages\telebot\util.py", line 93, in run
    task(*args, **kwargs)
  File "D:\Projects\enot-bot-python\venv\Lib\site-packages\telebot\__init__.py", line 677, in __retrieve_updates
    updates = self.get_updates(offset=(self.last_update_id + 1),
             ^^^^^^^^^^^^^^^^^^^^^^^^^^^^^^^^^^^^^^^^^^^^^^^^^^
  File "D:\Projects\enot-bot-python\venv\Lib\site-packages\telebot\__init__.py", line 649, in get_updates
    json_updates = apihelper.get_updates(
                   ^^^^^^^^^^^^^^^^^^^^^^
  File "D:\Projects\enot-bot-python\venv\Lib\site-packages\telebot\apihelper.py", line 330, in get_updates
    return _make_request(token, method_url, params=payload)
           ^^^^^^^^^^^^^^^^^^^^^^^^^^^^^^^^^^^^^^^^^^^^^^^^
  File "D:\Projects\enot-bot-python\venv\Lib\site-packages\telebot\apihelper.py", line 168, in _make_request
    json_result = _check_result(method_name, result)
                  ^^^^^^^^^^^^^^^^^^^^^^^^^^^^^^^^^^
  File "D:\Projects\enot-bot-python\venv\Lib\site-packages\telebot\apihelper.py", line 195, in _check_result
    raise ApiTelegramException(method_name, result, result_json)
telebot.apihelper.ApiTelegramException: A request to the Telegram API was unsuccessful. Error code: 409. Description: Conflict: terminated by other getUpdates request; make sure that only one bot instance is running

2024-08-11 04:55:06,975 - ERROR - Threaded polling exception: A request to the Telegram API was unsuccessful. Error code: 409. Description: Conflict: terminated by other getUpdates request; make sure that only one bot instance is running
2024-08-11 04:55:06,977 - ERROR - Exception traceback:
Traceback (most recent call last):
  File "D:\Projects\enot-bot-python\venv\Lib\site-packages\telebot\__init__.py", line 1215, in __threaded_polling
    polling_thread.raise_exceptions()
  File "D:\Projects\enot-bot-python\venv\Lib\site-packages\telebot\util.py", line 111, in raise_exceptions
    raise self.exception_info
  File "D:\Projects\enot-bot-python\venv\Lib\site-packages\telebot\util.py", line 93, in run
    task(*args, **kwargs)
  File "D:\Projects\enot-bot-python\venv\Lib\site-packages\telebot\__init__.py", line 677, in __retrieve_updates
    updates = self.get_updates(offset=(self.last_update_id + 1),
             ^^^^^^^^^^^^^^^^^^^^^^^^^^^^^^^^^^^^^^^^^^^^^^^^^^
  File "D:\Projects\enot-bot-python\venv\Lib\site-packages\telebot\__init__.py", line 649, in get_updates
    json_updates = apihelper.get_updates(
                   ^^^^^^^^^^^^^^^^^^^^^^
  File "D:\Projects\enot-bot-python\venv\Lib\site-packages\telebot\apihelper.py", line 330, in get_updates
    return _make_request(token, method_url, params=payload)
           ^^^^^^^^^^^^^^^^^^^^^^^^^^^^^^^^^^^^^^^^^^^^^^^^
  File "D:\Projects\enot-bot-python\venv\Lib\site-packages\telebot\apihelper.py", line 168, in _make_request
    json_result = _check_result(method_name, result)
                  ^^^^^^^^^^^^^^^^^^^^^^^^^^^^^^^^^^
  File "D:\Projects\enot-bot-python\venv\Lib\site-packages\telebot\apihelper.py", line 195, in _check_result
    raise ApiTelegramException(method_name, result, result_json)
telebot.apihelper.ApiTelegramException: A request to the Telegram API was unsuccessful. Error code: 409. Description: Conflict: terminated by other getUpdates request; make sure that only one bot instance is running

2024-08-11 04:55:10,135 - ERROR - Threaded polling exception: A request to the Telegram API was unsuccessful. Error code: 409. Description: Conflict: terminated by other getUpdates request; make sure that only one bot instance is running
2024-08-11 04:55:10,135 - ERROR - Exception traceback:
Traceback (most recent call last):
  File "D:\Projects\enot-bot-python\venv\Lib\site-packages\telebot\__init__.py", line 1215, in __threaded_polling
    polling_thread.raise_exceptions()
  File "D:\Projects\enot-bot-python\venv\Lib\site-packages\telebot\util.py", line 111, in raise_exceptions
    raise self.exception_info
  File "D:\Projects\enot-bot-python\venv\Lib\site-packages\telebot\util.py", line 93, in run
    task(*args, **kwargs)
  File "D:\Projects\enot-bot-python\venv\Lib\site-packages\telebot\__init__.py", line 677, in __retrieve_updates
    updates = self.get_updates(offset=(self.last_update_id + 1),
             ^^^^^^^^^^^^^^^^^^^^^^^^^^^^^^^^^^^^^^^^^^^^^^^^^^
  File "D:\Projects\enot-bot-python\venv\Lib\site-packages\telebot\__init__.py", line 649, in get_updates
    json_updates = apihelper.get_updates(
                   ^^^^^^^^^^^^^^^^^^^^^^
  File "D:\Projects\enot-bot-python\venv\Lib\site-packages\telebot\apihelper.py", line 330, in get_updates
    return _make_request(token, method_url, params=payload)
           ^^^^^^^^^^^^^^^^^^^^^^^^^^^^^^^^^^^^^^^^^^^^^^^^
  File "D:\Projects\enot-bot-python\venv\Lib\site-packages\telebot\apihelper.py", line 168, in _make_request
    json_result = _check_result(method_name, result)
                  ^^^^^^^^^^^^^^^^^^^^^^^^^^^^^^^^^^
  File "D:\Projects\enot-bot-python\venv\Lib\site-packages\telebot\apihelper.py", line 195, in _check_result
    raise ApiTelegramException(method_name, result, result_json)
telebot.apihelper.ApiTelegramException: A request to the Telegram API was unsuccessful. Error code: 409. Description: Conflict: terminated by other getUpdates request; make sure that only one bot instance is running

2024-08-11 04:55:10,315 - ERROR - Threaded polling exception: A request to the Telegram API was unsuccessful. Error code: 409. Description: Conflict: terminated by other getUpdates request; make sure that only one bot instance is running
2024-08-11 04:55:10,315 - ERROR - Exception traceback:
Traceback (most recent call last):
  File "D:\Projects\enot-bot-python\venv\Lib\site-packages\telebot\__init__.py", line 1215, in __threaded_polling
    polling_thread.raise_exceptions()
  File "D:\Projects\enot-bot-python\venv\Lib\site-packages\telebot\util.py", line 111, in raise_exceptions
    raise self.exception_info
  File "D:\Projects\enot-bot-python\venv\Lib\site-packages\telebot\util.py", line 93, in run
    task(*args, **kwargs)
  File "D:\Projects\enot-bot-python\venv\Lib\site-packages\telebot\__init__.py", line 677, in __retrieve_updates
    updates = self.get_updates(offset=(self.last_update_id + 1),
             ^^^^^^^^^^^^^^^^^^^^^^^^^^^^^^^^^^^^^^^^^^^^^^^^^^
  File "D:\Projects\enot-bot-python\venv\Lib\site-packages\telebot\__init__.py", line 649, in get_updates
    json_updates = apihelper.get_updates(
                   ^^^^^^^^^^^^^^^^^^^^^^
  File "D:\Projects\enot-bot-python\venv\Lib\site-packages\telebot\apihelper.py", line 330, in get_updates
    return _make_request(token, method_url, params=payload)
           ^^^^^^^^^^^^^^^^^^^^^^^^^^^^^^^^^^^^^^^^^^^^^^^^
  File "D:\Projects\enot-bot-python\venv\Lib\site-packages\telebot\apihelper.py", line 168, in _make_request
    json_result = _check_result(method_name, result)
                  ^^^^^^^^^^^^^^^^^^^^^^^^^^^^^^^^^^
  File "D:\Projects\enot-bot-python\venv\Lib\site-packages\telebot\apihelper.py", line 195, in _check_result
    raise ApiTelegramException(method_name, result, result_json)
telebot.apihelper.ApiTelegramException: A request to the Telegram API was unsuccessful. Error code: 409. Description: Conflict: terminated by other getUpdates request; make sure that only one bot instance is running

2024-08-11 04:55:13,470 - ERROR - Threaded polling exception: A request to the Telegram API was unsuccessful. Error code: 409. Description: Conflict: terminated by other getUpdates request; make sure that only one bot instance is running
2024-08-11 04:55:13,471 - ERROR - Exception traceback:
Traceback (most recent call last):
  File "D:\Projects\enot-bot-python\venv\Lib\site-packages\telebot\__init__.py", line 1215, in __threaded_polling
    polling_thread.raise_exceptions()
  File "D:\Projects\enot-bot-python\venv\Lib\site-packages\telebot\util.py", line 111, in raise_exceptions
    raise self.exception_info
  File "D:\Projects\enot-bot-python\venv\Lib\site-packages\telebot\util.py", line 93, in run
    task(*args, **kwargs)
  File "D:\Projects\enot-bot-python\venv\Lib\site-packages\telebot\__init__.py", line 677, in __retrieve_updates
    updates = self.get_updates(offset=(self.last_update_id + 1),
             ^^^^^^^^^^^^^^^^^^^^^^^^^^^^^^^^^^^^^^^^^^^^^^^^^^
  File "D:\Projects\enot-bot-python\venv\Lib\site-packages\telebot\__init__.py", line 649, in get_updates
    json_updates = apihelper.get_updates(
                   ^^^^^^^^^^^^^^^^^^^^^^
  File "D:\Projects\enot-bot-python\venv\Lib\site-packages\telebot\apihelper.py", line 330, in get_updates
    return _make_request(token, method_url, params=payload)
           ^^^^^^^^^^^^^^^^^^^^^^^^^^^^^^^^^^^^^^^^^^^^^^^^
  File "D:\Projects\enot-bot-python\venv\Lib\site-packages\telebot\apihelper.py", line 168, in _make_request
    json_result = _check_result(method_name, result)
                  ^^^^^^^^^^^^^^^^^^^^^^^^^^^^^^^^^^
  File "D:\Projects\enot-bot-python\venv\Lib\site-packages\telebot\apihelper.py", line 195, in _check_result
    raise ApiTelegramException(method_name, result, result_json)
telebot.apihelper.ApiTelegramException: A request to the Telegram API was unsuccessful. Error code: 409. Description: Conflict: terminated by other getUpdates request; make sure that only one bot instance is running

2024-08-11 04:55:13,656 - ERROR - Threaded polling exception: A request to the Telegram API was unsuccessful. Error code: 409. Description: Conflict: terminated by other getUpdates request; make sure that only one bot instance is running
2024-08-11 04:55:13,657 - ERROR - Exception traceback:
Traceback (most recent call last):
  File "D:\Projects\enot-bot-python\venv\Lib\site-packages\telebot\__init__.py", line 1215, in __threaded_polling
    polling_thread.raise_exceptions()
  File "D:\Projects\enot-bot-python\venv\Lib\site-packages\telebot\util.py", line 111, in raise_exceptions
    raise self.exception_info
  File "D:\Projects\enot-bot-python\venv\Lib\site-packages\telebot\util.py", line 93, in run
    task(*args, **kwargs)
  File "D:\Projects\enot-bot-python\venv\Lib\site-packages\telebot\__init__.py", line 677, in __retrieve_updates
    updates = self.get_updates(offset=(self.last_update_id + 1),
             ^^^^^^^^^^^^^^^^^^^^^^^^^^^^^^^^^^^^^^^^^^^^^^^^^^
  File "D:\Projects\enot-bot-python\venv\Lib\site-packages\telebot\__init__.py", line 649, in get_updates
    json_updates = apihelper.get_updates(
                   ^^^^^^^^^^^^^^^^^^^^^^
  File "D:\Projects\enot-bot-python\venv\Lib\site-packages\telebot\apihelper.py", line 330, in get_updates
    return _make_request(token, method_url, params=payload)
           ^^^^^^^^^^^^^^^^^^^^^^^^^^^^^^^^^^^^^^^^^^^^^^^^
  File "D:\Projects\enot-bot-python\venv\Lib\site-packages\telebot\apihelper.py", line 168, in _make_request
    json_result = _check_result(method_name, result)
                  ^^^^^^^^^^^^^^^^^^^^^^^^^^^^^^^^^^
  File "D:\Projects\enot-bot-python\venv\Lib\site-packages\telebot\apihelper.py", line 195, in _check_result
    raise ApiTelegramException(method_name, result, result_json)
telebot.apihelper.ApiTelegramException: A request to the Telegram API was unsuccessful. Error code: 409. Description: Conflict: terminated by other getUpdates request; make sure that only one bot instance is running

2024-08-11 04:55:16,824 - ERROR - Threaded polling exception: A request to the Telegram API was unsuccessful. Error code: 409. Description: Conflict: terminated by other getUpdates request; make sure that only one bot instance is running
2024-08-11 04:55:16,825 - ERROR - Exception traceback:
Traceback (most recent call last):
  File "D:\Projects\enot-bot-python\venv\Lib\site-packages\telebot\__init__.py", line 1215, in __threaded_polling
    polling_thread.raise_exceptions()
  File "D:\Projects\enot-bot-python\venv\Lib\site-packages\telebot\util.py", line 111, in raise_exceptions
    raise self.exception_info
  File "D:\Projects\enot-bot-python\venv\Lib\site-packages\telebot\util.py", line 93, in run
    task(*args, **kwargs)
  File "D:\Projects\enot-bot-python\venv\Lib\site-packages\telebot\__init__.py", line 677, in __retrieve_updates
    updates = self.get_updates(offset=(self.last_update_id + 1),
             ^^^^^^^^^^^^^^^^^^^^^^^^^^^^^^^^^^^^^^^^^^^^^^^^^^
  File "D:\Projects\enot-bot-python\venv\Lib\site-packages\telebot\__init__.py", line 649, in get_updates
    json_updates = apihelper.get_updates(
                   ^^^^^^^^^^^^^^^^^^^^^^
  File "D:\Projects\enot-bot-python\venv\Lib\site-packages\telebot\apihelper.py", line 330, in get_updates
    return _make_request(token, method_url, params=payload)
           ^^^^^^^^^^^^^^^^^^^^^^^^^^^^^^^^^^^^^^^^^^^^^^^^
  File "D:\Projects\enot-bot-python\venv\Lib\site-packages\telebot\apihelper.py", line 168, in _make_request
    json_result = _check_result(method_name, result)
                  ^^^^^^^^^^^^^^^^^^^^^^^^^^^^^^^^^^
  File "D:\Projects\enot-bot-python\venv\Lib\site-packages\telebot\apihelper.py", line 195, in _check_result
    raise ApiTelegramException(method_name, result, result_json)
telebot.apihelper.ApiTelegramException: A request to the Telegram API was unsuccessful. Error code: 409. Description: Conflict: terminated by other getUpdates request; make sure that only one bot instance is running

2024-08-11 04:55:16,976 - ERROR - Threaded polling exception: A request to the Telegram API was unsuccessful. Error code: 409. Description: Conflict: terminated by other getUpdates request; make sure that only one bot instance is running
2024-08-11 04:55:16,978 - ERROR - Exception traceback:
Traceback (most recent call last):
  File "D:\Projects\enot-bot-python\venv\Lib\site-packages\telebot\__init__.py", line 1215, in __threaded_polling
    polling_thread.raise_exceptions()
  File "D:\Projects\enot-bot-python\venv\Lib\site-packages\telebot\util.py", line 111, in raise_exceptions
    raise self.exception_info
  File "D:\Projects\enot-bot-python\venv\Lib\site-packages\telebot\util.py", line 93, in run
    task(*args, **kwargs)
  File "D:\Projects\enot-bot-python\venv\Lib\site-packages\telebot\__init__.py", line 677, in __retrieve_updates
    updates = self.get_updates(offset=(self.last_update_id + 1),
             ^^^^^^^^^^^^^^^^^^^^^^^^^^^^^^^^^^^^^^^^^^^^^^^^^^
  File "D:\Projects\enot-bot-python\venv\Lib\site-packages\telebot\__init__.py", line 649, in get_updates
    json_updates = apihelper.get_updates(
                   ^^^^^^^^^^^^^^^^^^^^^^
  File "D:\Projects\enot-bot-python\venv\Lib\site-packages\telebot\apihelper.py", line 330, in get_updates
    return _make_request(token, method_url, params=payload)
           ^^^^^^^^^^^^^^^^^^^^^^^^^^^^^^^^^^^^^^^^^^^^^^^^
  File "D:\Projects\enot-bot-python\venv\Lib\site-packages\telebot\apihelper.py", line 168, in _make_request
    json_result = _check_result(method_name, result)
                  ^^^^^^^^^^^^^^^^^^^^^^^^^^^^^^^^^^
  File "D:\Projects\enot-bot-python\venv\Lib\site-packages\telebot\apihelper.py", line 195, in _check_result
    raise ApiTelegramException(method_name, result, result_json)
telebot.apihelper.ApiTelegramException: A request to the Telegram API was unsuccessful. Error code: 409. Description: Conflict: terminated by other getUpdates request; make sure that only one bot instance is running

2024-08-11 04:55:24,584 - INFO - Starting bot
2024-08-11 04:55:24,903 - ERROR - Threaded polling exception: A request to the Telegram API was unsuccessful. Error code: 409. Description: Conflict: terminated by other getUpdates request; make sure that only one bot instance is running
2024-08-11 04:55:24,904 - ERROR - Exception traceback:
Traceback (most recent call last):
  File "D:\Projects\enot-bot-python\venv\Lib\site-packages\telebot\__init__.py", line 1215, in __threaded_polling
    polling_thread.raise_exceptions()
  File "D:\Projects\enot-bot-python\venv\Lib\site-packages\telebot\util.py", line 111, in raise_exceptions
    raise self.exception_info
  File "D:\Projects\enot-bot-python\venv\Lib\site-packages\telebot\util.py", line 93, in run
    task(*args, **kwargs)
  File "D:\Projects\enot-bot-python\venv\Lib\site-packages\telebot\__init__.py", line 677, in __retrieve_updates
    updates = self.get_updates(offset=(self.last_update_id + 1),
             ^^^^^^^^^^^^^^^^^^^^^^^^^^^^^^^^^^^^^^^^^^^^^^^^^^
  File "D:\Projects\enot-bot-python\venv\Lib\site-packages\telebot\__init__.py", line 649, in get_updates
    json_updates = apihelper.get_updates(
                   ^^^^^^^^^^^^^^^^^^^^^^
  File "D:\Projects\enot-bot-python\venv\Lib\site-packages\telebot\apihelper.py", line 330, in get_updates
    return _make_request(token, method_url, params=payload)
           ^^^^^^^^^^^^^^^^^^^^^^^^^^^^^^^^^^^^^^^^^^^^^^^^
  File "D:\Projects\enot-bot-python\venv\Lib\site-packages\telebot\apihelper.py", line 168, in _make_request
    json_result = _check_result(method_name, result)
                  ^^^^^^^^^^^^^^^^^^^^^^^^^^^^^^^^^^
  File "D:\Projects\enot-bot-python\venv\Lib\site-packages\telebot\apihelper.py", line 195, in _check_result
    raise ApiTelegramException(method_name, result, result_json)
telebot.apihelper.ApiTelegramException: A request to the Telegram API was unsuccessful. Error code: 409. Description: Conflict: terminated by other getUpdates request; make sure that only one bot instance is running

2024-08-11 04:55:28,053 - ERROR - Threaded polling exception: A request to the Telegram API was unsuccessful. Error code: 409. Description: Conflict: terminated by other getUpdates request; make sure that only one bot instance is running
2024-08-11 04:55:28,054 - ERROR - Exception traceback:
Traceback (most recent call last):
  File "D:\Projects\enot-bot-python\venv\Lib\site-packages\telebot\__init__.py", line 1215, in __threaded_polling
    polling_thread.raise_exceptions()
  File "D:\Projects\enot-bot-python\venv\Lib\site-packages\telebot\util.py", line 111, in raise_exceptions
    raise self.exception_info
  File "D:\Projects\enot-bot-python\venv\Lib\site-packages\telebot\util.py", line 93, in run
    task(*args, **kwargs)
  File "D:\Projects\enot-bot-python\venv\Lib\site-packages\telebot\__init__.py", line 677, in __retrieve_updates
    updates = self.get_updates(offset=(self.last_update_id + 1),
             ^^^^^^^^^^^^^^^^^^^^^^^^^^^^^^^^^^^^^^^^^^^^^^^^^^
  File "D:\Projects\enot-bot-python\venv\Lib\site-packages\telebot\__init__.py", line 649, in get_updates
    json_updates = apihelper.get_updates(
                   ^^^^^^^^^^^^^^^^^^^^^^
  File "D:\Projects\enot-bot-python\venv\Lib\site-packages\telebot\apihelper.py", line 330, in get_updates
    return _make_request(token, method_url, params=payload)
           ^^^^^^^^^^^^^^^^^^^^^^^^^^^^^^^^^^^^^^^^^^^^^^^^
  File "D:\Projects\enot-bot-python\venv\Lib\site-packages\telebot\apihelper.py", line 168, in _make_request
    json_result = _check_result(method_name, result)
                  ^^^^^^^^^^^^^^^^^^^^^^^^^^^^^^^^^^
  File "D:\Projects\enot-bot-python\venv\Lib\site-packages\telebot\apihelper.py", line 195, in _check_result
    raise ApiTelegramException(method_name, result, result_json)
telebot.apihelper.ApiTelegramException: A request to the Telegram API was unsuccessful. Error code: 409. Description: Conflict: terminated by other getUpdates request; make sure that only one bot instance is running

2024-08-11 04:55:28,237 - ERROR - Threaded polling exception: A request to the Telegram API was unsuccessful. Error code: 409. Description: Conflict: terminated by other getUpdates request; make sure that only one bot instance is running
2024-08-11 04:55:28,238 - ERROR - Exception traceback:
Traceback (most recent call last):
  File "D:\Projects\enot-bot-python\venv\Lib\site-packages\telebot\__init__.py", line 1215, in __threaded_polling
    polling_thread.raise_exceptions()
  File "D:\Projects\enot-bot-python\venv\Lib\site-packages\telebot\util.py", line 111, in raise_exceptions
    raise self.exception_info
  File "D:\Projects\enot-bot-python\venv\Lib\site-packages\telebot\util.py", line 93, in run
    task(*args, **kwargs)
  File "D:\Projects\enot-bot-python\venv\Lib\site-packages\telebot\__init__.py", line 677, in __retrieve_updates
    updates = self.get_updates(offset=(self.last_update_id + 1),
             ^^^^^^^^^^^^^^^^^^^^^^^^^^^^^^^^^^^^^^^^^^^^^^^^^^
  File "D:\Projects\enot-bot-python\venv\Lib\site-packages\telebot\__init__.py", line 649, in get_updates
    json_updates = apihelper.get_updates(
                   ^^^^^^^^^^^^^^^^^^^^^^
  File "D:\Projects\enot-bot-python\venv\Lib\site-packages\telebot\apihelper.py", line 330, in get_updates
    return _make_request(token, method_url, params=payload)
           ^^^^^^^^^^^^^^^^^^^^^^^^^^^^^^^^^^^^^^^^^^^^^^^^
  File "D:\Projects\enot-bot-python\venv\Lib\site-packages\telebot\apihelper.py", line 168, in _make_request
    json_result = _check_result(method_name, result)
                  ^^^^^^^^^^^^^^^^^^^^^^^^^^^^^^^^^^
  File "D:\Projects\enot-bot-python\venv\Lib\site-packages\telebot\apihelper.py", line 195, in _check_result
    raise ApiTelegramException(method_name, result, result_json)
telebot.apihelper.ApiTelegramException: A request to the Telegram API was unsuccessful. Error code: 409. Description: Conflict: terminated by other getUpdates request; make sure that only one bot instance is running

2024-08-11 04:55:31,390 - ERROR - Threaded polling exception: A request to the Telegram API was unsuccessful. Error code: 409. Description: Conflict: terminated by other getUpdates request; make sure that only one bot instance is running
2024-08-11 04:55:31,391 - ERROR - Exception traceback:
Traceback (most recent call last):
  File "D:\Projects\enot-bot-python\venv\Lib\site-packages\telebot\__init__.py", line 1215, in __threaded_polling
    polling_thread.raise_exceptions()
  File "D:\Projects\enot-bot-python\venv\Lib\site-packages\telebot\util.py", line 111, in raise_exceptions
    raise self.exception_info
  File "D:\Projects\enot-bot-python\venv\Lib\site-packages\telebot\util.py", line 93, in run
    task(*args, **kwargs)
  File "D:\Projects\enot-bot-python\venv\Lib\site-packages\telebot\__init__.py", line 677, in __retrieve_updates
    updates = self.get_updates(offset=(self.last_update_id + 1),
             ^^^^^^^^^^^^^^^^^^^^^^^^^^^^^^^^^^^^^^^^^^^^^^^^^^
  File "D:\Projects\enot-bot-python\venv\Lib\site-packages\telebot\__init__.py", line 649, in get_updates
    json_updates = apihelper.get_updates(
                   ^^^^^^^^^^^^^^^^^^^^^^
  File "D:\Projects\enot-bot-python\venv\Lib\site-packages\telebot\apihelper.py", line 330, in get_updates
    return _make_request(token, method_url, params=payload)
           ^^^^^^^^^^^^^^^^^^^^^^^^^^^^^^^^^^^^^^^^^^^^^^^^
  File "D:\Projects\enot-bot-python\venv\Lib\site-packages\telebot\apihelper.py", line 168, in _make_request
    json_result = _check_result(method_name, result)
                  ^^^^^^^^^^^^^^^^^^^^^^^^^^^^^^^^^^
  File "D:\Projects\enot-bot-python\venv\Lib\site-packages\telebot\apihelper.py", line 195, in _check_result
    raise ApiTelegramException(method_name, result, result_json)
telebot.apihelper.ApiTelegramException: A request to the Telegram API was unsuccessful. Error code: 409. Description: Conflict: terminated by other getUpdates request; make sure that only one bot instance is running

2024-08-11 04:55:31,777 - ERROR - Threaded polling exception: A request to the Telegram API was unsuccessful. Error code: 409. Description: Conflict: terminated by other getUpdates request; make sure that only one bot instance is running
2024-08-11 04:55:31,778 - ERROR - Exception traceback:
Traceback (most recent call last):
  File "D:\Projects\enot-bot-python\venv\Lib\site-packages\telebot\__init__.py", line 1215, in __threaded_polling
    polling_thread.raise_exceptions()
  File "D:\Projects\enot-bot-python\venv\Lib\site-packages\telebot\util.py", line 111, in raise_exceptions
    raise self.exception_info
  File "D:\Projects\enot-bot-python\venv\Lib\site-packages\telebot\util.py", line 93, in run
    task(*args, **kwargs)
  File "D:\Projects\enot-bot-python\venv\Lib\site-packages\telebot\__init__.py", line 677, in __retrieve_updates
    updates = self.get_updates(offset=(self.last_update_id + 1),
             ^^^^^^^^^^^^^^^^^^^^^^^^^^^^^^^^^^^^^^^^^^^^^^^^^^
  File "D:\Projects\enot-bot-python\venv\Lib\site-packages\telebot\__init__.py", line 649, in get_updates
    json_updates = apihelper.get_updates(
                   ^^^^^^^^^^^^^^^^^^^^^^
  File "D:\Projects\enot-bot-python\venv\Lib\site-packages\telebot\apihelper.py", line 330, in get_updates
    return _make_request(token, method_url, params=payload)
           ^^^^^^^^^^^^^^^^^^^^^^^^^^^^^^^^^^^^^^^^^^^^^^^^
  File "D:\Projects\enot-bot-python\venv\Lib\site-packages\telebot\apihelper.py", line 168, in _make_request
    json_result = _check_result(method_name, result)
                  ^^^^^^^^^^^^^^^^^^^^^^^^^^^^^^^^^^
  File "D:\Projects\enot-bot-python\venv\Lib\site-packages\telebot\apihelper.py", line 195, in _check_result
    raise ApiTelegramException(method_name, result, result_json)
telebot.apihelper.ApiTelegramException: A request to the Telegram API was unsuccessful. Error code: 409. Description: Conflict: terminated by other getUpdates request; make sure that only one bot instance is running

2024-08-11 04:55:35,093 - ERROR - Threaded polling exception: A request to the Telegram API was unsuccessful. Error code: 409. Description: Conflict: terminated by other getUpdates request; make sure that only one bot instance is running
2024-08-11 04:55:35,094 - ERROR - Exception traceback:
Traceback (most recent call last):
  File "D:\Projects\enot-bot-python\venv\Lib\site-packages\telebot\__init__.py", line 1215, in __threaded_polling
    polling_thread.raise_exceptions()
  File "D:\Projects\enot-bot-python\venv\Lib\site-packages\telebot\util.py", line 111, in raise_exceptions
    raise self.exception_info
  File "D:\Projects\enot-bot-python\venv\Lib\site-packages\telebot\util.py", line 93, in run
    task(*args, **kwargs)
  File "D:\Projects\enot-bot-python\venv\Lib\site-packages\telebot\__init__.py", line 677, in __retrieve_updates
    updates = self.get_updates(offset=(self.last_update_id + 1),
             ^^^^^^^^^^^^^^^^^^^^^^^^^^^^^^^^^^^^^^^^^^^^^^^^^^
  File "D:\Projects\enot-bot-python\venv\Lib\site-packages\telebot\__init__.py", line 649, in get_updates
    json_updates = apihelper.get_updates(
                   ^^^^^^^^^^^^^^^^^^^^^^
  File "D:\Projects\enot-bot-python\venv\Lib\site-packages\telebot\apihelper.py", line 330, in get_updates
    return _make_request(token, method_url, params=payload)
           ^^^^^^^^^^^^^^^^^^^^^^^^^^^^^^^^^^^^^^^^^^^^^^^^
  File "D:\Projects\enot-bot-python\venv\Lib\site-packages\telebot\apihelper.py", line 168, in _make_request
    json_result = _check_result(method_name, result)
                  ^^^^^^^^^^^^^^^^^^^^^^^^^^^^^^^^^^
  File "D:\Projects\enot-bot-python\venv\Lib\site-packages\telebot\apihelper.py", line 195, in _check_result
    raise ApiTelegramException(method_name, result, result_json)
telebot.apihelper.ApiTelegramException: A request to the Telegram API was unsuccessful. Error code: 409. Description: Conflict: terminated by other getUpdates request; make sure that only one bot instance is running

2024-08-11 04:56:15,245 - INFO - Starting bot
2024-08-11 04:57:46,327 - INFO - response for -1002088136062: {"message":"Participants saved to database","status":"success"}

2024-08-11 05:01:50,906 - INFO - Starting bot
2024-08-11 05:02:58,106 - INFO - Starting bot
2024-08-11 05:03:18,457 - INFO - response for -1002088136062: {"message":"Participants saved to database","status":"success"}

2024-08-11 05:03:34,574 - INFO - response for -1002088136062: {"message":"Participants saved to database","status":"success"}

2024-08-11 05:04:24,445 - ERROR - Error occurred: handle_update() missing 1 required positional argument: 'silent'
